import unittest
import model_utils as utils
import pandas as pd

from pydataset import data
from sklearn.model_selection import train_test_split

class TestModelUtils(unittest.TestCase):

    train, test = train_test_split(data("iris"), test_size=.2, random_state=1414)
    train2, test2 = train_test_split(data("swiss"), test_size=.2, random_state=1414)
    train, validate = train_test_split(train, test_size=.3, random_state=1414)
    train2, validate2 = train_test_split(train2, test_size=.3, random_state=1414)

    def test_generate_xy_splits_positive(self):
        result = utils.generate_xy_splits(self.train, self.validate, self.test, target="Species")

        self.assertEqual(["X_train", "y_train", "X_validate", "y_validate", "X_test", "y_test"],
            list(result.keys()))
        self.assertFalse("Species" in result['X_train'])
        self.assertFalse("Species" in result['X_validate'])
        self.assertFalse("Species" in result['X_test'])
        self.assertIsNotNone(result['y_train'])
        self.assertIsNotNone(result['y_validate'])
        self.assertIsNotNone(result['y_test'])
        self.assertEqual(pd.DataFrame, type(result['y_train']))
        self.assertEqual(pd.DataFrame, type(result['y_validate']))
        self.assertEqual(pd.DataFrame, type(result['y_test']))

    def test_generate_xy_splits_drop_columns_positive(self):
        result = utils.generate_xy_splits(self.train, self.validate, self.test, target="Species", drop_columns=["Sepal.Width", "Petal.Width"])

        self.assertFalse("Sepal.Width" in result['X_train'])
        self.assertFalse("Sepal.Width" in result['X_validate'])
        self.assertFalse("Sepal.Width" in result['X_test'])
        self.assertFalse("Petal.Width" in result['X_train'])
        self.assertFalse("Petal.Width" in result['X_validate'])
        self.assertFalse("Petal.Width" in result['X_test'])

    # This test reproduced a situation where a KeyError occurred when calling generate_xy_splits without specifying a drop_columns list
    # on two different dataframes within the same scope. It should pass without the error occurring.
    def test_generate_xy_splits_key_error(self):
        utils.generate_xy_splits(self.train, self.validate, self.test, target='Species')
        utils.generate_xy_splits(self.train2, self.validate2, self.test2, target='Fertility')

if __name__ == "__main__":
    unittest.main()